[2025-06-26T18:30:03.393+0700] {local_task_job_runner.py:120} INFO - ::group::Pre task execution logs
[2025-06-26T18:30:03.412+0700] {taskinstance.py:2073} INFO - Dependencies all met for dep_context=non-requeueable deps ti=<TaskInstance: send_data_to_powerbi.send_to_power_bi scheduled__2025-06-26T11:20:00+00:00 [queued]>
[2025-06-26T18:30:03.417+0700] {taskinstance.py:2073} INFO - Dependencies all met for dep_context=requeueable deps ti=<TaskInstance: send_data_to_powerbi.send_to_power_bi scheduled__2025-06-26T11:20:00+00:00 [queued]>
[2025-06-26T18:30:03.417+0700] {taskinstance.py:2303} INFO - Starting attempt 1 of 3
[2025-06-26T18:30:03.434+0700] {taskinstance.py:2327} INFO - Executing <Task(PythonOperator): send_to_power_bi> on 2025-06-26 11:20:00+00:00
[2025-06-26T18:30:03.439+0700] {standard_task_runner.py:63} INFO - Started process 14089 to run task
[2025-06-26T18:30:03.444+0700] {standard_task_runner.py:90} INFO - Running: ['airflow', 'tasks', 'run', 'send_data_to_powerbi', 'send_to_power_bi', 'scheduled__2025-06-26T11:20:00+00:00', '--job-id', '53', '--raw', '--subdir', 'DAGS_FOLDER/load_power_bi.py', '--cfg-path', '/tmp/tmpuin5ogg8']
[2025-06-26T18:30:03.445+0700] {standard_task_runner.py:91} INFO - Job 53: Subtask send_to_power_bi
[2025-06-26T18:30:03.484+0700] {task_command.py:426} INFO - Running <TaskInstance: send_data_to_powerbi.send_to_power_bi scheduled__2025-06-26T11:20:00+00:00 [running]> on host Panda
[2025-06-26T18:30:03.537+0700] {taskinstance.py:2644} INFO - Exporting env vars: AIRFLOW_CTX_DAG_OWNER='group_03' AIRFLOW_CTX_DAG_ID='send_data_to_powerbi' AIRFLOW_CTX_TASK_ID='send_to_power_bi' AIRFLOW_CTX_EXECUTION_DATE='2025-06-26T11:20:00+00:00' AIRFLOW_CTX_TRY_NUMBER='1' AIRFLOW_CTX_DAG_RUN_ID='scheduled__2025-06-26T11:20:00+00:00'
[2025-06-26T18:30:03.538+0700] {taskinstance.py:430} INFO - ::endgroup::
[2025-06-26T18:30:03.542+0700] {client.py:1116} INFO - Listing '/transactions_by_hour_compacted/'.
[2025-06-26T18:30:03.552+0700] {taskinstance.py:441} INFO - ::group::Post task execution logs
[2025-06-26T18:30:03.553+0700] {taskinstance.py:2890} ERROR - Task failed with exception
Traceback (most recent call last):
  File "/home/panda/Documents/ODAP/Project/venv310/lib/python3.10/site-packages/airflow/models/taskinstance.py", line 465, in _execute_task
    result = _execute_callable(context=context, **execute_callable_kwargs)
  File "/home/panda/Documents/ODAP/Project/venv310/lib/python3.10/site-packages/airflow/models/taskinstance.py", line 432, in _execute_callable
    return execute_callable(context=context, **execute_callable_kwargs)
  File "/home/panda/Documents/ODAP/Project/venv310/lib/python3.10/site-packages/airflow/models/baseoperator.py", line 400, in wrapper
    return func(self, *args, **kwargs)
  File "/home/panda/Documents/ODAP/Project/venv310/lib/python3.10/site-packages/airflow/operators/python.py", line 235, in execute
    return_value = self.execute_callable()
  File "/home/panda/Documents/ODAP/Project/venv310/lib/python3.10/site-packages/airflow/operators/python.py", line 252, in execute_callable
    return self.python_callable(*self.op_args, **self.op_kwargs)
  File "/home/panda/Documents/ODAP/Project/airflow/dags/load_power_bi.py", line 43, in send_new_data
    files = HDFS_CLIENT.list(FOLDER_HDFS_PATH)
  File "/home/panda/Documents/ODAP/Project/venv310/lib/python3.10/site-packages/hdfs/client.py", line 1118, in list
    statuses = self._list_status(hdfs_path).json()['FileStatuses']['FileStatus']
  File "/home/panda/Documents/ODAP/Project/venv310/lib/python3.10/site-packages/hdfs/client.py", line 118, in api_handler
    raise err
hdfs.util.HdfsError: File /transactions_by_hour_compacted does not exist.
[2025-06-26T18:30:03.556+0700] {taskinstance.py:1205} INFO - Marking task as UP_FOR_RETRY. dag_id=send_data_to_powerbi, task_id=send_to_power_bi, execution_date=20250626T112000, start_date=20250626T113003, end_date=20250626T113003
[2025-06-26T18:30:03.573+0700] {standard_task_runner.py:110} ERROR - Failed to execute job 53 for task send_to_power_bi (File /transactions_by_hour_compacted does not exist.; 14089)
[2025-06-26T18:30:03.614+0700] {local_task_job_runner.py:240} INFO - Task exited with return code 1
[2025-06-26T18:30:03.629+0700] {taskinstance.py:3482} INFO - 0 downstream tasks scheduled from follow-on schedule check
[2025-06-26T18:30:03.630+0700] {local_task_job_runner.py:222} INFO - ::endgroup::
[2025-06-26T18:34:51.069+0700] {local_task_job_runner.py:120} INFO - ::group::Pre task execution logs
[2025-06-26T18:34:51.088+0700] {taskinstance.py:2063} INFO - Dependencies not met for <TaskInstance: send_data_to_powerbi.send_to_power_bi scheduled__2025-06-26T11:20:00+00:00 [skipped]>, dependency 'Task Instance State' FAILED: Task is in the 'skipped' state.
[2025-06-26T18:34:51.088+0700] {local_task_job_runner.py:163} INFO - Task is not able to be run
[2025-06-26T18:38:51.642+0700] {local_task_job_runner.py:120} INFO - ::group::Pre task execution logs
[2025-06-26T18:38:51.662+0700] {taskinstance.py:2073} INFO - Dependencies all met for dep_context=non-requeueable deps ti=<TaskInstance: send_data_to_powerbi.send_to_power_bi scheduled__2025-06-26T11:20:00+00:00 [queued]>
[2025-06-26T18:38:51.668+0700] {taskinstance.py:2073} INFO - Dependencies all met for dep_context=requeueable deps ti=<TaskInstance: send_data_to_powerbi.send_to_power_bi scheduled__2025-06-26T11:20:00+00:00 [queued]>
[2025-06-26T18:38:51.668+0700] {taskinstance.py:2303} INFO - Starting attempt 1 of 3
[2025-06-26T18:38:51.684+0700] {taskinstance.py:2327} INFO - Executing <Task(PythonOperator): send_to_power_bi> on 2025-06-26 11:20:00+00:00
[2025-06-26T18:38:51.695+0700] {standard_task_runner.py:63} INFO - Started process 18295 to run task
[2025-06-26T18:38:51.699+0700] {standard_task_runner.py:90} INFO - Running: ['airflow', 'tasks', 'run', 'send_data_to_powerbi', 'send_to_power_bi', 'scheduled__2025-06-26T11:20:00+00:00', '--job-id', '51', '--raw', '--subdir', 'DAGS_FOLDER/load_power_bi.py', '--cfg-path', '/tmp/tmpqwo_0mu2']
[2025-06-26T18:38:51.700+0700] {standard_task_runner.py:91} INFO - Job 51: Subtask send_to_power_bi
[2025-06-26T18:38:51.746+0700] {task_command.py:426} INFO - Running <TaskInstance: send_data_to_powerbi.send_to_power_bi scheduled__2025-06-26T11:20:00+00:00 [running]> on host Panda
[2025-06-26T18:38:51.812+0700] {taskinstance.py:2644} INFO - Exporting env vars: AIRFLOW_CTX_DAG_OWNER='group_03' AIRFLOW_CTX_DAG_ID='send_data_to_powerbi' AIRFLOW_CTX_TASK_ID='send_to_power_bi' AIRFLOW_CTX_EXECUTION_DATE='2025-06-26T11:20:00+00:00' AIRFLOW_CTX_TRY_NUMBER='1' AIRFLOW_CTX_DAG_RUN_ID='scheduled__2025-06-26T11:20:00+00:00'
[2025-06-26T18:38:51.813+0700] {taskinstance.py:430} INFO - ::endgroup::
[2025-06-26T18:38:51.817+0700] {client.py:1116} INFO - Listing '/transactions_by_hour_compacted/'.
[2025-06-26T18:38:51.831+0700] {client.py:724} INFO - Reading file '/transactions_by_hour_compacted/part-00000-88431b04-8c7a-44cc-8c0d-44db9bcd438a-c000.csv'.
[2025-06-26T18:38:52.417+0700] {taskinstance.py:441} INFO - ::group::Post task execution logs
[2025-06-26T18:38:52.418+0700] {taskinstance.py:2890} ERROR - Task failed with exception
Traceback (most recent call last):
  File "/home/panda/Documents/ODAP/Project/venv310/lib/python3.10/site-packages/airflow/models/taskinstance.py", line 465, in _execute_task
    result = _execute_callable(context=context, **execute_callable_kwargs)
  File "/home/panda/Documents/ODAP/Project/venv310/lib/python3.10/site-packages/airflow/models/taskinstance.py", line 432, in _execute_callable
    return execute_callable(context=context, **execute_callable_kwargs)
  File "/home/panda/Documents/ODAP/Project/venv310/lib/python3.10/site-packages/airflow/models/baseoperator.py", line 400, in wrapper
    return func(self, *args, **kwargs)
  File "/home/panda/Documents/ODAP/Project/venv310/lib/python3.10/site-packages/airflow/operators/python.py", line 235, in execute
    return_value = self.execute_callable()
  File "/home/panda/Documents/ODAP/Project/venv310/lib/python3.10/site-packages/airflow/operators/python.py", line 252, in execute_callable
    return self.python_callable(*self.op_args, **self.op_kwargs)
  File "/home/panda/Documents/ODAP/Project/airflow/dags/load_power_bi.py", line 70, in send_new_data
    if pd.to_datetime(row["event_time"], utc=True) > last_push_time:
  File "pandas/_libs/tslibs/timestamps.pyx", line 387, in pandas._libs.tslibs.timestamps._Timestamp.__richcmp__
TypeError: Cannot compare tz-naive and tz-aware timestamps
[2025-06-26T18:38:52.424+0700] {taskinstance.py:1205} INFO - Marking task as UP_FOR_RETRY. dag_id=send_data_to_powerbi, task_id=send_to_power_bi, execution_date=20250626T112000, start_date=20250626T113851, end_date=20250626T113852
[2025-06-26T18:38:52.438+0700] {standard_task_runner.py:110} ERROR - Failed to execute job 51 for task send_to_power_bi (Cannot compare tz-naive and tz-aware timestamps; 18295)
[2025-06-26T18:38:52.473+0700] {local_task_job_runner.py:240} INFO - Task exited with return code 1
[2025-06-26T18:38:52.492+0700] {taskinstance.py:3482} INFO - 0 downstream tasks scheduled from follow-on schedule check
[2025-06-26T18:38:52.494+0700] {local_task_job_runner.py:222} INFO - ::endgroup::
