[2025-06-26T18:32:06.423+0700] {local_task_job_runner.py:120} INFO - ::group::Pre task execution logs
[2025-06-26T18:32:06.442+0700] {taskinstance.py:2073} INFO - Dependencies all met for dep_context=non-requeueable deps ti=<TaskInstance: send_data_to_powerbi.send_to_power_bi scheduled__2025-06-26T11:20:00+00:00 [queued]>
[2025-06-26T18:32:06.447+0700] {taskinstance.py:2073} INFO - Dependencies all met for dep_context=requeueable deps ti=<TaskInstance: send_data_to_powerbi.send_to_power_bi scheduled__2025-06-26T11:20:00+00:00 [queued]>
[2025-06-26T18:32:06.447+0700] {taskinstance.py:2303} INFO - Starting attempt 2 of 3
[2025-06-26T18:32:06.464+0700] {taskinstance.py:2327} INFO - Executing <Task(PythonOperator): send_to_power_bi> on 2025-06-26 11:20:00+00:00
[2025-06-26T18:32:06.470+0700] {standard_task_runner.py:63} INFO - Started process 14544 to run task
[2025-06-26T18:32:06.474+0700] {standard_task_runner.py:90} INFO - Running: ['airflow', 'tasks', 'run', 'send_data_to_powerbi', 'send_to_power_bi', 'scheduled__2025-06-26T11:20:00+00:00', '--job-id', '54', '--raw', '--subdir', 'DAGS_FOLDER/load_power_bi.py', '--cfg-path', '/tmp/tmpbdfr58hk']
[2025-06-26T18:32:06.475+0700] {standard_task_runner.py:91} INFO - Job 54: Subtask send_to_power_bi
[2025-06-26T18:32:06.522+0700] {task_command.py:426} INFO - Running <TaskInstance: send_data_to_powerbi.send_to_power_bi scheduled__2025-06-26T11:20:00+00:00 [running]> on host Panda
[2025-06-26T18:32:06.574+0700] {taskinstance.py:2644} INFO - Exporting env vars: AIRFLOW_CTX_DAG_OWNER='group_03' AIRFLOW_CTX_DAG_ID='send_data_to_powerbi' AIRFLOW_CTX_TASK_ID='send_to_power_bi' AIRFLOW_CTX_EXECUTION_DATE='2025-06-26T11:20:00+00:00' AIRFLOW_CTX_TRY_NUMBER='2' AIRFLOW_CTX_DAG_RUN_ID='scheduled__2025-06-26T11:20:00+00:00'
[2025-06-26T18:32:06.575+0700] {taskinstance.py:430} INFO - ::endgroup::
[2025-06-26T18:32:06.579+0700] {client.py:1116} INFO - Listing '/transactions_by_hour_compacted/'.
[2025-06-26T18:32:06.591+0700] {taskinstance.py:441} INFO - ::group::Post task execution logs
[2025-06-26T18:32:06.592+0700] {taskinstance.py:2890} ERROR - Task failed with exception
Traceback (most recent call last):
  File "/home/panda/Documents/ODAP/Project/venv310/lib/python3.10/site-packages/airflow/models/taskinstance.py", line 465, in _execute_task
    result = _execute_callable(context=context, **execute_callable_kwargs)
  File "/home/panda/Documents/ODAP/Project/venv310/lib/python3.10/site-packages/airflow/models/taskinstance.py", line 432, in _execute_callable
    return execute_callable(context=context, **execute_callable_kwargs)
  File "/home/panda/Documents/ODAP/Project/venv310/lib/python3.10/site-packages/airflow/models/baseoperator.py", line 400, in wrapper
    return func(self, *args, **kwargs)
  File "/home/panda/Documents/ODAP/Project/venv310/lib/python3.10/site-packages/airflow/operators/python.py", line 235, in execute
    return_value = self.execute_callable()
  File "/home/panda/Documents/ODAP/Project/venv310/lib/python3.10/site-packages/airflow/operators/python.py", line 252, in execute_callable
    return self.python_callable(*self.op_args, **self.op_kwargs)
  File "/home/panda/Documents/ODAP/Project/airflow/dags/load_power_bi.py", line 43, in send_new_data
    files = HDFS_CLIENT.list(FOLDER_HDFS_PATH)
  File "/home/panda/Documents/ODAP/Project/venv310/lib/python3.10/site-packages/hdfs/client.py", line 1118, in list
    statuses = self._list_status(hdfs_path).json()['FileStatuses']['FileStatus']
  File "/home/panda/Documents/ODAP/Project/venv310/lib/python3.10/site-packages/hdfs/client.py", line 118, in api_handler
    raise err
hdfs.util.HdfsError: File /transactions_by_hour_compacted does not exist.
[2025-06-26T18:32:06.596+0700] {taskinstance.py:1205} INFO - Marking task as UP_FOR_RETRY. dag_id=send_data_to_powerbi, task_id=send_to_power_bi, execution_date=20250626T112000, start_date=20250626T113206, end_date=20250626T113206
[2025-06-26T18:32:06.612+0700] {standard_task_runner.py:110} ERROR - Failed to execute job 54 for task send_to_power_bi (File /transactions_by_hour_compacted does not exist.; 14544)
[2025-06-26T18:32:06.645+0700] {local_task_job_runner.py:240} INFO - Task exited with return code 1
[2025-06-26T18:32:06.660+0700] {taskinstance.py:3482} INFO - 0 downstream tasks scheduled from follow-on schedule check
[2025-06-26T18:32:06.660+0700] {local_task_job_runner.py:222} INFO - ::endgroup::
[2025-06-26T18:40:54.745+0700] {local_task_job_runner.py:120} INFO - ::group::Pre task execution logs
[2025-06-26T18:40:54.765+0700] {taskinstance.py:2073} INFO - Dependencies all met for dep_context=non-requeueable deps ti=<TaskInstance: send_data_to_powerbi.send_to_power_bi scheduled__2025-06-26T11:20:00+00:00 [queued]>
[2025-06-26T18:40:54.770+0700] {taskinstance.py:2073} INFO - Dependencies all met for dep_context=requeueable deps ti=<TaskInstance: send_data_to_powerbi.send_to_power_bi scheduled__2025-06-26T11:20:00+00:00 [queued]>
[2025-06-26T18:40:54.770+0700] {taskinstance.py:2303} INFO - Starting attempt 2 of 3
[2025-06-26T18:40:54.786+0700] {taskinstance.py:2327} INFO - Executing <Task(PythonOperator): send_to_power_bi> on 2025-06-26 11:20:00+00:00
[2025-06-26T18:40:54.795+0700] {standard_task_runner.py:63} INFO - Started process 20331 to run task
[2025-06-26T18:40:54.799+0700] {standard_task_runner.py:90} INFO - Running: ['airflow', 'tasks', 'run', 'send_data_to_powerbi', 'send_to_power_bi', 'scheduled__2025-06-26T11:20:00+00:00', '--job-id', '54', '--raw', '--subdir', 'DAGS_FOLDER/load_power_bi.py', '--cfg-path', '/tmp/tmpkvkdzn_i']
[2025-06-26T18:40:54.800+0700] {standard_task_runner.py:91} INFO - Job 54: Subtask send_to_power_bi
[2025-06-26T18:40:54.856+0700] {task_command.py:426} INFO - Running <TaskInstance: send_data_to_powerbi.send_to_power_bi scheduled__2025-06-26T11:20:00+00:00 [running]> on host Panda
[2025-06-26T18:40:54.928+0700] {taskinstance.py:2644} INFO - Exporting env vars: AIRFLOW_CTX_DAG_OWNER='group_03' AIRFLOW_CTX_DAG_ID='send_data_to_powerbi' AIRFLOW_CTX_TASK_ID='send_to_power_bi' AIRFLOW_CTX_EXECUTION_DATE='2025-06-26T11:20:00+00:00' AIRFLOW_CTX_TRY_NUMBER='2' AIRFLOW_CTX_DAG_RUN_ID='scheduled__2025-06-26T11:20:00+00:00'
[2025-06-26T18:40:54.929+0700] {taskinstance.py:430} INFO - ::endgroup::
[2025-06-26T18:40:54.933+0700] {client.py:1116} INFO - Listing '/transactions_by_hour_compacted/'.
[2025-06-26T18:40:54.945+0700] {client.py:724} INFO - Reading file '/transactions_by_hour_compacted/part-00000-e7a280b9-84b6-4c35-8759-7d6dd9a9c1b6-c000.csv'.
[2025-06-26T18:40:54.994+0700] {taskinstance.py:441} INFO - ::group::Post task execution logs
[2025-06-26T18:40:54.995+0700] {taskinstance.py:2890} ERROR - Task failed with exception
Traceback (most recent call last):
  File "/home/panda/Documents/ODAP/Project/venv310/lib/python3.10/site-packages/airflow/models/taskinstance.py", line 465, in _execute_task
    result = _execute_callable(context=context, **execute_callable_kwargs)
  File "/home/panda/Documents/ODAP/Project/venv310/lib/python3.10/site-packages/airflow/models/taskinstance.py", line 432, in _execute_callable
    return execute_callable(context=context, **execute_callable_kwargs)
  File "/home/panda/Documents/ODAP/Project/venv310/lib/python3.10/site-packages/airflow/models/baseoperator.py", line 400, in wrapper
    return func(self, *args, **kwargs)
  File "/home/panda/Documents/ODAP/Project/venv310/lib/python3.10/site-packages/airflow/operators/python.py", line 235, in execute
    return_value = self.execute_callable()
  File "/home/panda/Documents/ODAP/Project/venv310/lib/python3.10/site-packages/airflow/operators/python.py", line 252, in execute_callable
    return self.python_callable(*self.op_args, **self.op_kwargs)
  File "/home/panda/Documents/ODAP/Project/airflow/dags/load_power_bi.py", line 70, in send_new_data
    if pd.to_datetime(row["event_time"], utc=True) > last_push_time:
  File "pandas/_libs/tslibs/timestamps.pyx", line 387, in pandas._libs.tslibs.timestamps._Timestamp.__richcmp__
TypeError: Cannot compare tz-naive and tz-aware timestamps
[2025-06-26T18:40:55.000+0700] {taskinstance.py:1205} INFO - Marking task as UP_FOR_RETRY. dag_id=send_data_to_powerbi, task_id=send_to_power_bi, execution_date=20250626T112000, start_date=20250626T114054, end_date=20250626T114055
[2025-06-26T18:40:55.020+0700] {standard_task_runner.py:110} ERROR - Failed to execute job 54 for task send_to_power_bi (Cannot compare tz-naive and tz-aware timestamps; 20331)
[2025-06-26T18:40:55.051+0700] {local_task_job_runner.py:240} INFO - Task exited with return code 1
[2025-06-26T18:40:55.068+0700] {taskinstance.py:3482} INFO - 0 downstream tasks scheduled from follow-on schedule check
[2025-06-26T18:40:55.069+0700] {local_task_job_runner.py:222} INFO - ::endgroup::
