[2025-06-24T00:55:12.511+0700] {local_task_job_runner.py:120} INFO - ::group::Pre task execution logs
[2025-06-24T00:55:12.539+0700] {taskinstance.py:2073} INFO - Dependencies all met for dep_context=non-requeueable deps ti=<TaskInstance: start_kafka_hadoop_and_run_notebooks.start_zookeeper manual__2025-06-23T17:55:09.439441+00:00 [queued]>
[2025-06-24T00:55:12.544+0700] {taskinstance.py:2073} INFO - Dependencies all met for dep_context=requeueable deps ti=<TaskInstance: start_kafka_hadoop_and_run_notebooks.start_zookeeper manual__2025-06-23T17:55:09.439441+00:00 [queued]>
[2025-06-24T00:55:12.544+0700] {taskinstance.py:2303} INFO - Starting attempt 1 of 4
[2025-06-24T00:55:12.559+0700] {taskinstance.py:2327} INFO - Executing <Task(BashOperator): start_zookeeper> on 2025-06-23 17:55:09.439441+00:00
[2025-06-24T00:55:12.565+0700] {standard_task_runner.py:63} INFO - Started process 25808 to run task
[2025-06-24T00:55:12.570+0700] {standard_task_runner.py:90} INFO - Running: ['airflow', 'tasks', 'run', 'start_kafka_hadoop_and_run_notebooks', 'start_zookeeper', 'manual__2025-06-23T17:55:09.439441+00:00', '--job-id', '37', '--raw', '--subdir', 'DAGS_FOLDER/start_DAG.py', '--cfg-path', '/tmp/tmp3vuop9_3']
[2025-06-24T00:55:12.571+0700] {standard_task_runner.py:91} INFO - Job 37: Subtask start_zookeeper
[2025-06-24T00:55:12.619+0700] {task_command.py:426} INFO - Running <TaskInstance: start_kafka_hadoop_and_run_notebooks.start_zookeeper manual__2025-06-23T17:55:09.439441+00:00 [running]> on host Panda
[2025-06-24T00:55:12.699+0700] {taskinstance.py:2644} INFO - Exporting env vars: AIRFLOW_CTX_DAG_OWNER='group_03' AIRFLOW_CTX_DAG_ID='start_kafka_hadoop_and_run_notebooks' AIRFLOW_CTX_TASK_ID='start_zookeeper' AIRFLOW_CTX_EXECUTION_DATE='2025-06-23T17:55:09.439441+00:00' AIRFLOW_CTX_TRY_NUMBER='1' AIRFLOW_CTX_DAG_RUN_ID='manual__2025-06-23T17:55:09.439441+00:00'
[2025-06-24T00:55:12.700+0700] {taskinstance.py:430} INFO - ::endgroup::
[2025-06-24T00:55:12.701+0700] {subprocess.py:63} INFO - Tmp dir root location: /tmp
[2025-06-24T00:55:12.701+0700] {subprocess.py:75} INFO - Running command: ['/usr/bin/bash', '-c', 'cd /home/panda/kafka_2.13-3.9.1 && nohup bin/zookeeper-server-start.sh config/zookeeper.properties > /tmp/zookeeper.log 2>&1 & sleep 5 && exit 0']
[2025-06-24T00:55:12.716+0700] {subprocess.py:86} INFO - Output:
[2025-06-24T01:02:51.519+0700] {local_task_job_runner.py:310} WARNING - State of this instance has been externally set to None. Terminating instance.
[2025-06-24T01:02:51.519+0700] {local_task_job_runner.py:222} INFO - ::endgroup::
[2025-06-24T01:02:51.531+0700] {process_utils.py:132} INFO - Sending Signals.SIGTERM to group 25808. PIDs of all processes in the group: [25809, 25808]
[2025-06-24T01:02:51.532+0700] {process_utils.py:87} INFO - Sending the signal Signals.SIGTERM to group 25808
[2025-06-24T01:02:51.532+0700] {taskinstance.py:2607} ERROR - Received SIGTERM. Terminating subprocesses.
[2025-06-24T01:02:51.532+0700] {subprocess.py:104} INFO - Sending SIGTERM signal to process group
[2025-06-24T01:02:51.533+0700] {taskinstance.py:441} INFO - ::group::Post task execution logs
[2025-06-24T01:02:51.541+0700] {taskinstance.py:2890} ERROR - Task failed with exception
Traceback (most recent call last):
  File "/home/panda/Documents/ODAP/Project/venv310/lib/python3.10/site-packages/airflow/models/taskinstance.py", line 465, in _execute_task
    result = _execute_callable(context=context, **execute_callable_kwargs)
  File "/home/panda/Documents/ODAP/Project/venv310/lib/python3.10/site-packages/airflow/models/taskinstance.py", line 432, in _execute_callable
    return execute_callable(context=context, **execute_callable_kwargs)
  File "/home/panda/Documents/ODAP/Project/venv310/lib/python3.10/site-packages/airflow/models/baseoperator.py", line 400, in wrapper
    return func(self, *args, **kwargs)
  File "/home/panda/Documents/ODAP/Project/venv310/lib/python3.10/site-packages/airflow/operators/bash.py", line 234, in execute
    result = self.subprocess_hook.run_command(
  File "/home/panda/Documents/ODAP/Project/venv310/lib/python3.10/site-packages/airflow/hooks/subprocess.py", line 91, in run_command
    for raw_line in iter(self.sub_process.stdout.readline, b""):
  File "/home/panda/Documents/ODAP/Project/venv310/lib/python3.10/site-packages/airflow/models/taskinstance.py", line 2609, in signal_handler
    raise AirflowTaskTerminated("Task received SIGTERM signal")
airflow.exceptions.AirflowTaskTerminated: Task received SIGTERM signal
[2025-06-24T01:02:51.545+0700] {taskinstance.py:1205} INFO - Marking task as UP_FOR_RETRY. dag_id=start_kafka_hadoop_and_run_notebooks, task_id=start_zookeeper, execution_date=20250623T175509, start_date=20250623T175512, end_date=20250623T180251
[2025-06-24T01:02:51.558+0700] {standard_task_runner.py:110} ERROR - Failed to execute job 37 for task start_zookeeper ((sqlite3.IntegrityError) FOREIGN KEY constraint failed
[SQL: INSERT INTO task_fail (task_id, dag_id, run_id, map_index, start_date, end_date, duration) VALUES (?, ?, ?, ?, ?, ?, ?)]
[parameters: ('start_zookeeper', 'start_kafka_hadoop_and_run_notebooks', 'manual__2025-06-23T17:55:09.439441+00:00', -1, '2025-06-23 17:55:12.539598', '2025-06-23 18:02:51.544602', 459)]
(Background on this error at: https://sqlalche.me/e/14/gkpj); 25808)
[2025-06-24T01:02:51.584+0700] {process_utils.py:80} INFO - Process psutil.Process(pid=25808, status='terminated', exitcode=1, started='00:55:11') (25808) terminated with exit code 1
[2025-06-24T01:02:51.584+0700] {process_utils.py:80} INFO - Process psutil.Process(pid=25809, status='terminated', started='00:55:11') (25809) terminated with exit code None
