[2025-06-22T15:52:00.150+0700] {local_task_job_runner.py:120} INFO - ::group::Pre task execution logs
[2025-06-22T15:52:00.177+0700] {taskinstance.py:2073} INFO - Dependencies all met for dep_context=non-requeueable deps ti=<TaskInstance: start_kafka_hadoop_and_run_notebooks.start_yarn manual__2025-06-22T08:46:29.704023+00:00 [queued]>
[2025-06-22T15:52:00.183+0700] {taskinstance.py:2073} INFO - Dependencies all met for dep_context=requeueable deps ti=<TaskInstance: start_kafka_hadoop_and_run_notebooks.start_yarn manual__2025-06-22T08:46:29.704023+00:00 [queued]>
[2025-06-22T15:52:00.183+0700] {taskinstance.py:2303} INFO - Starting attempt 2 of 4
[2025-06-22T15:52:00.200+0700] {taskinstance.py:2327} INFO - Executing <Task(BashOperator): start_yarn> on 2025-06-22 08:46:29.704023+00:00
[2025-06-22T15:52:00.207+0700] {standard_task_runner.py:63} INFO - Started process 54734 to run task
[2025-06-22T15:52:00.213+0700] {standard_task_runner.py:90} INFO - Running: ['airflow', 'tasks', 'run', 'start_kafka_hadoop_and_run_notebooks', 'start_yarn', 'manual__2025-06-22T08:46:29.704023+00:00', '--job-id', '17', '--raw', '--subdir', 'DAGS_FOLDER/start_DAG.py', '--cfg-path', '/tmp/tmplsd_f7ya']
[2025-06-22T15:52:00.214+0700] {standard_task_runner.py:91} INFO - Job 17: Subtask start_yarn
[2025-06-22T15:52:00.271+0700] {task_command.py:426} INFO - Running <TaskInstance: start_kafka_hadoop_and_run_notebooks.start_yarn manual__2025-06-22T08:46:29.704023+00:00 [running]> on host Panda
[2025-06-22T15:52:00.332+0700] {taskinstance.py:2644} INFO - Exporting env vars: AIRFLOW_CTX_DAG_OWNER='group_03' AIRFLOW_CTX_DAG_ID='start_kafka_hadoop_and_run_notebooks' AIRFLOW_CTX_TASK_ID='start_yarn' AIRFLOW_CTX_EXECUTION_DATE='2025-06-22T08:46:29.704023+00:00' AIRFLOW_CTX_TRY_NUMBER='2' AIRFLOW_CTX_DAG_RUN_ID='manual__2025-06-22T08:46:29.704023+00:00'
[2025-06-22T15:52:00.333+0700] {taskinstance.py:430} INFO - ::endgroup::
[2025-06-22T15:52:00.334+0700] {subprocess.py:63} INFO - Tmp dir root location: /tmp
[2025-06-22T15:52:00.334+0700] {subprocess.py:75} INFO - Running command: ['/usr/bin/bash', '-c', "'start-yarn.sh'"]
[2025-06-22T15:52:00.348+0700] {subprocess.py:86} INFO - Output:
[2025-06-22T15:52:01.239+0700] {subprocess.py:93} INFO - Starting resourcemanager
[2025-06-22T15:52:01.344+0700] {subprocess.py:93} INFO - resourcemanager is running as process 42892.  Stop it first and ensure /tmp/hadoop-panda-resourcemanager.pid file is empty before retry.
[2025-06-22T15:52:01.345+0700] {subprocess.py:93} INFO - Starting nodemanagers
[2025-06-22T15:52:01.812+0700] {subprocess.py:93} INFO - localhost: nodemanager is running as process 43058.  Stop it first and ensure /tmp/hadoop-panda-nodemanager.pid file is empty before retry.
[2025-06-22T15:52:02.603+0700] {subprocess.py:97} INFO - Command exited with return code 1
[2025-06-22T15:52:02.604+0700] {taskinstance.py:441} INFO - ::group::Post task execution logs
[2025-06-22T15:52:02.611+0700] {taskinstance.py:2890} ERROR - Task failed with exception
Traceback (most recent call last):
  File "/home/panda/Documents/ODAP/Project/venv310/lib/python3.10/site-packages/airflow/models/taskinstance.py", line 465, in _execute_task
    result = _execute_callable(context=context, **execute_callable_kwargs)
  File "/home/panda/Documents/ODAP/Project/venv310/lib/python3.10/site-packages/airflow/models/taskinstance.py", line 432, in _execute_callable
    return execute_callable(context=context, **execute_callable_kwargs)
  File "/home/panda/Documents/ODAP/Project/venv310/lib/python3.10/site-packages/airflow/models/baseoperator.py", line 400, in wrapper
    return func(self, *args, **kwargs)
  File "/home/panda/Documents/ODAP/Project/venv310/lib/python3.10/site-packages/airflow/operators/bash.py", line 243, in execute
    raise AirflowException(
airflow.exceptions.AirflowException: Bash command failed. The command returned a non-zero exit code 1.
[2025-06-22T15:52:02.614+0700] {taskinstance.py:1205} INFO - Marking task as UP_FOR_RETRY. dag_id=start_kafka_hadoop_and_run_notebooks, task_id=start_yarn, execution_date=20250622T084629, start_date=20250622T085200, end_date=20250622T085202
[2025-06-22T15:52:02.630+0700] {standard_task_runner.py:110} ERROR - Failed to execute job 17 for task start_yarn (Bash command failed. The command returned a non-zero exit code 1.; 54734)
[2025-06-22T15:52:02.672+0700] {local_task_job_runner.py:240} INFO - Task exited with return code 1
[2025-06-22T15:52:02.689+0700] {taskinstance.py:3482} INFO - 0 downstream tasks scheduled from follow-on schedule check
[2025-06-22T15:52:02.689+0700] {local_task_job_runner.py:222} INFO - ::endgroup::
