[2025-06-24T00:37:13.227+0700] {local_task_job_runner.py:120} INFO - ::group::Pre task execution logs
[2025-06-24T00:37:13.246+0700] {taskinstance.py:2073} INFO - Dependencies all met for dep_context=non-requeueable deps ti=<TaskInstance: start_kafka_hadoop_and_run_notebooks.start_zookeeper manual__2025-06-23T17:37:10.818892+00:00 [queued]>
[2025-06-24T00:37:13.252+0700] {taskinstance.py:2073} INFO - Dependencies all met for dep_context=requeueable deps ti=<TaskInstance: start_kafka_hadoop_and_run_notebooks.start_zookeeper manual__2025-06-23T17:37:10.818892+00:00 [queued]>
[2025-06-24T00:37:13.252+0700] {taskinstance.py:2303} INFO - Starting attempt 1 of 4
[2025-06-24T00:37:13.269+0700] {taskinstance.py:2327} INFO - Executing <Task(BashOperator): start_zookeeper> on 2025-06-23 17:37:10.818892+00:00
[2025-06-24T00:37:13.274+0700] {standard_task_runner.py:63} INFO - Started process 21238 to run task
[2025-06-24T00:37:13.279+0700] {standard_task_runner.py:90} INFO - Running: ['airflow', 'tasks', 'run', 'start_kafka_hadoop_and_run_notebooks', 'start_zookeeper', 'manual__2025-06-23T17:37:10.818892+00:00', '--job-id', '36', '--raw', '--subdir', 'DAGS_FOLDER/start_DAG.py', '--cfg-path', '/tmp/tmp46uor5o9']
[2025-06-24T00:37:13.279+0700] {standard_task_runner.py:91} INFO - Job 36: Subtask start_zookeeper
[2025-06-24T00:37:13.320+0700] {task_command.py:426} INFO - Running <TaskInstance: start_kafka_hadoop_and_run_notebooks.start_zookeeper manual__2025-06-23T17:37:10.818892+00:00 [running]> on host Panda
[2025-06-24T00:37:13.390+0700] {taskinstance.py:2644} INFO - Exporting env vars: AIRFLOW_CTX_DAG_OWNER='group_03' AIRFLOW_CTX_DAG_ID='start_kafka_hadoop_and_run_notebooks' AIRFLOW_CTX_TASK_ID='start_zookeeper' AIRFLOW_CTX_EXECUTION_DATE='2025-06-23T17:37:10.818892+00:00' AIRFLOW_CTX_TRY_NUMBER='1' AIRFLOW_CTX_DAG_RUN_ID='manual__2025-06-23T17:37:10.818892+00:00'
[2025-06-24T00:37:13.391+0700] {taskinstance.py:430} INFO - ::endgroup::
[2025-06-24T00:37:13.392+0700] {subprocess.py:63} INFO - Tmp dir root location: /tmp
[2025-06-24T00:37:13.392+0700] {subprocess.py:75} INFO - Running command: ['/usr/bin/bash', '-c', '\n        cd /home/panda/kafka_2.13-3.9.1 &&         nohup bin/zookeeper-server-start.sh config/zookeeper.properties > /tmp/zookeeper.log 2>&1 &\n        sleep 5 && exit 0\n        ']
[2025-06-24T00:37:13.405+0700] {subprocess.py:86} INFO - Output:
[2025-06-24T00:52:16.617+0700] {local_task_job_runner.py:310} WARNING - State of this instance has been externally set to None. Terminating instance.
[2025-06-24T00:52:16.618+0700] {local_task_job_runner.py:222} INFO - ::endgroup::
[2025-06-24T00:52:16.630+0700] {process_utils.py:132} INFO - Sending Signals.SIGTERM to group 21238. PIDs of all processes in the group: [21239, 21238]
[2025-06-24T00:52:16.630+0700] {process_utils.py:87} INFO - Sending the signal Signals.SIGTERM to group 21238
[2025-06-24T00:52:16.631+0700] {taskinstance.py:2607} ERROR - Received SIGTERM. Terminating subprocesses.
[2025-06-24T00:52:16.631+0700] {subprocess.py:104} INFO - Sending SIGTERM signal to process group
[2025-06-24T00:52:16.632+0700] {taskinstance.py:441} INFO - ::group::Post task execution logs
[2025-06-24T00:52:16.641+0700] {taskinstance.py:2890} ERROR - Task failed with exception
Traceback (most recent call last):
  File "/home/panda/Documents/ODAP/Project/venv310/lib/python3.10/site-packages/airflow/models/taskinstance.py", line 465, in _execute_task
    result = _execute_callable(context=context, **execute_callable_kwargs)
  File "/home/panda/Documents/ODAP/Project/venv310/lib/python3.10/site-packages/airflow/models/taskinstance.py", line 432, in _execute_callable
    return execute_callable(context=context, **execute_callable_kwargs)
  File "/home/panda/Documents/ODAP/Project/venv310/lib/python3.10/site-packages/airflow/models/baseoperator.py", line 400, in wrapper
    return func(self, *args, **kwargs)
  File "/home/panda/Documents/ODAP/Project/venv310/lib/python3.10/site-packages/airflow/operators/bash.py", line 234, in execute
    result = self.subprocess_hook.run_command(
  File "/home/panda/Documents/ODAP/Project/venv310/lib/python3.10/site-packages/airflow/hooks/subprocess.py", line 91, in run_command
    for raw_line in iter(self.sub_process.stdout.readline, b""):
  File "/home/panda/Documents/ODAP/Project/venv310/lib/python3.10/site-packages/airflow/models/taskinstance.py", line 2609, in signal_handler
    raise AirflowTaskTerminated("Task received SIGTERM signal")
airflow.exceptions.AirflowTaskTerminated: Task received SIGTERM signal
[2025-06-24T00:52:16.644+0700] {taskinstance.py:1205} INFO - Marking task as UP_FOR_RETRY. dag_id=start_kafka_hadoop_and_run_notebooks, task_id=start_zookeeper, execution_date=20250623T173710, start_date=20250623T173713, end_date=20250623T175216
[2025-06-24T00:52:16.656+0700] {standard_task_runner.py:110} ERROR - Failed to execute job 36 for task start_zookeeper ((sqlite3.IntegrityError) FOREIGN KEY constraint failed
[SQL: INSERT INTO task_fail (task_id, dag_id, run_id, map_index, start_date, end_date, duration) VALUES (?, ?, ?, ?, ?, ?, ?)]
[parameters: ('start_zookeeper', 'start_kafka_hadoop_and_run_notebooks', 'manual__2025-06-23T17:37:10.818892+00:00', -1, '2025-06-23 17:37:13.247225', '2025-06-23 17:52:16.643620', 903)]
(Background on this error at: https://sqlalche.me/e/14/gkpj); 21238)
[2025-06-24T00:52:16.683+0700] {process_utils.py:80} INFO - Process psutil.Process(pid=21238, status='terminated', exitcode=1, started='00:37:12') (21238) terminated with exit code 1
[2025-06-24T00:52:16.684+0700] {process_utils.py:80} INFO - Process psutil.Process(pid=21239, status='terminated', started='00:37:12') (21239) terminated with exit code None
