[2025-06-22T15:52:12.350+0700] {local_task_job_runner.py:120} INFO - ::group::Pre task execution logs
[2025-06-22T15:52:12.371+0700] {taskinstance.py:2073} INFO - Dependencies all met for dep_context=non-requeueable deps ti=<TaskInstance: start_kafka_hadoop_and_run_notebooks.start_yarn manual__2025-06-22T08:46:35.834149+00:00 [queued]>
[2025-06-22T15:52:12.377+0700] {taskinstance.py:2073} INFO - Dependencies all met for dep_context=requeueable deps ti=<TaskInstance: start_kafka_hadoop_and_run_notebooks.start_yarn manual__2025-06-22T08:46:35.834149+00:00 [queued]>
[2025-06-22T15:52:12.377+0700] {taskinstance.py:2303} INFO - Starting attempt 2 of 4
[2025-06-22T15:52:12.397+0700] {taskinstance.py:2327} INFO - Executing <Task(BashOperator): start_yarn> on 2025-06-22 08:46:35.834149+00:00
[2025-06-22T15:52:12.401+0700] {standard_task_runner.py:63} INFO - Started process 55106 to run task
[2025-06-22T15:52:12.406+0700] {standard_task_runner.py:90} INFO - Running: ['airflow', 'tasks', 'run', 'start_kafka_hadoop_and_run_notebooks', 'start_yarn', 'manual__2025-06-22T08:46:35.834149+00:00', '--job-id', '18', '--raw', '--subdir', 'DAGS_FOLDER/start_DAG.py', '--cfg-path', '/tmp/tmpej7o1rsb']
[2025-06-22T15:52:12.407+0700] {standard_task_runner.py:91} INFO - Job 18: Subtask start_yarn
[2025-06-22T15:52:12.470+0700] {task_command.py:426} INFO - Running <TaskInstance: start_kafka_hadoop_and_run_notebooks.start_yarn manual__2025-06-22T08:46:35.834149+00:00 [running]> on host Panda
[2025-06-22T15:52:12.543+0700] {taskinstance.py:2644} INFO - Exporting env vars: AIRFLOW_CTX_DAG_OWNER='group_03' AIRFLOW_CTX_DAG_ID='start_kafka_hadoop_and_run_notebooks' AIRFLOW_CTX_TASK_ID='start_yarn' AIRFLOW_CTX_EXECUTION_DATE='2025-06-22T08:46:35.834149+00:00' AIRFLOW_CTX_TRY_NUMBER='2' AIRFLOW_CTX_DAG_RUN_ID='manual__2025-06-22T08:46:35.834149+00:00'
[2025-06-22T15:52:12.544+0700] {taskinstance.py:430} INFO - ::endgroup::
[2025-06-22T15:52:12.545+0700] {subprocess.py:63} INFO - Tmp dir root location: /tmp
[2025-06-22T15:52:12.545+0700] {subprocess.py:75} INFO - Running command: ['/usr/bin/bash', '-c', "'start-yarn.sh'"]
[2025-06-22T15:52:12.560+0700] {subprocess.py:86} INFO - Output:
[2025-06-22T15:52:13.442+0700] {subprocess.py:93} INFO - Starting resourcemanager
[2025-06-22T15:52:13.543+0700] {subprocess.py:93} INFO - resourcemanager is running as process 42892.  Stop it first and ensure /tmp/hadoop-panda-resourcemanager.pid file is empty before retry.
[2025-06-22T15:52:13.543+0700] {subprocess.py:93} INFO - Starting nodemanagers
[2025-06-22T15:52:14.011+0700] {subprocess.py:93} INFO - localhost: nodemanager is running as process 43058.  Stop it first and ensure /tmp/hadoop-panda-nodemanager.pid file is empty before retry.
[2025-06-22T15:52:14.849+0700] {subprocess.py:97} INFO - Command exited with return code 1
[2025-06-22T15:52:14.851+0700] {taskinstance.py:441} INFO - ::group::Post task execution logs
[2025-06-22T15:52:14.859+0700] {taskinstance.py:2890} ERROR - Task failed with exception
Traceback (most recent call last):
  File "/home/panda/Documents/ODAP/Project/venv310/lib/python3.10/site-packages/airflow/models/taskinstance.py", line 465, in _execute_task
    result = _execute_callable(context=context, **execute_callable_kwargs)
  File "/home/panda/Documents/ODAP/Project/venv310/lib/python3.10/site-packages/airflow/models/taskinstance.py", line 432, in _execute_callable
    return execute_callable(context=context, **execute_callable_kwargs)
  File "/home/panda/Documents/ODAP/Project/venv310/lib/python3.10/site-packages/airflow/models/baseoperator.py", line 400, in wrapper
    return func(self, *args, **kwargs)
  File "/home/panda/Documents/ODAP/Project/venv310/lib/python3.10/site-packages/airflow/operators/bash.py", line 243, in execute
    raise AirflowException(
airflow.exceptions.AirflowException: Bash command failed. The command returned a non-zero exit code 1.
[2025-06-22T15:52:14.862+0700] {taskinstance.py:1205} INFO - Marking task as UP_FOR_RETRY. dag_id=start_kafka_hadoop_and_run_notebooks, task_id=start_yarn, execution_date=20250622T084635, start_date=20250622T085212, end_date=20250622T085214
[2025-06-22T15:52:14.882+0700] {standard_task_runner.py:110} ERROR - Failed to execute job 18 for task start_yarn (Bash command failed. The command returned a non-zero exit code 1.; 55106)
[2025-06-22T15:52:14.904+0700] {local_task_job_runner.py:240} INFO - Task exited with return code 1
[2025-06-22T15:52:14.920+0700] {taskinstance.py:3482} INFO - 0 downstream tasks scheduled from follow-on schedule check
[2025-06-22T15:52:14.921+0700] {local_task_job_runner.py:222} INFO - ::endgroup::
